test_login_success (接口.test_login.TestLogin) ... ERROR
test_recharge (接口.test_cases.test_recharge.TestRecharge) ... ok

======================================================================
ERROR: test_login_success (接口.test_login.TestLogin)
----------------------------------------------------------------------
Traceback (most recent call last):
  File "D:\python\lib\site-packages\urllib3\connection.py", line 175, in _new_conn
    (self._dns_host, self.port), self.timeout, **extra_kw
  File "D:\python\lib\site-packages\urllib3\util\connection.py", line 95, in create_connection
    raise err
  File "D:\python\lib\site-packages\urllib3\util\connection.py", line 85, in create_connection
    sock.connect(sa)
ConnectionRefusedError: [WinError 10061] 由于目标计算机积极拒绝，无法连接。

During handling of the above exception, another exception occurred:

Traceback (most recent call last):
  File "D:\python\lib\site-packages\urllib3\connectionpool.py", line 710, in urlopen
    chunked=chunked,
  File "D:\python\lib\site-packages\urllib3\connectionpool.py", line 398, in _make_request
    conn.request(method, url, **httplib_request_kw)
  File "D:\python\lib\site-packages\urllib3\connection.py", line 239, in request
    super(HTTPConnection, self).request(method, url, body=body, headers=headers)
  File "D:\python\lib\http\client.py", line 1252, in request
    self._send_request(method, url, body, headers, encode_chunked)
  File "D:\python\lib\http\client.py", line 1298, in _send_request
    self.endheaders(body, encode_chunked=encode_chunked)
  File "D:\python\lib\http\client.py", line 1247, in endheaders
    self._send_output(message_body, encode_chunked=encode_chunked)
  File "D:\python\lib\http\client.py", line 1026, in _send_output
    self.send(msg)
  File "D:\python\lib\http\client.py", line 966, in send
    self.connect()
  File "D:\python\lib\site-packages\urllib3\connection.py", line 205, in connect
    conn = self._new_conn()
  File "D:\python\lib\site-packages\urllib3\connection.py", line 187, in _new_conn
    self, "Failed to establish a new connection: %s" % e
urllib3.exceptions.NewConnectionError: <urllib3.connection.HTTPConnection object at 0x0000000003564488>: Failed to establish a new connection: [WinError 10061] 由于目标计算机积极拒绝，无法连接。

During handling of the above exception, another exception occurred:

Traceback (most recent call last):
  File "D:\python\lib\site-packages\requests\adapters.py", line 450, in send
    timeout=timeout
  File "D:\python\lib\site-packages\urllib3\connectionpool.py", line 786, in urlopen
    method, url, error=e, _pool=self, _stacktrace=sys.exc_info()[2]
  File "D:\python\lib\site-packages\urllib3\util\retry.py", line 592, in increment
    raise MaxRetryError(_pool, url, error or ResponseError(cause))
urllib3.exceptions.MaxRetryError: HTTPConnectionPool(host='localhost', port=5000): Max retries exceeded with url: /login (Caused by NewConnectionError('<urllib3.connection.HTTPConnection object at 0x0000000003564488>: Failed to establish a new connection: [WinError 10061] 由于目标计算机积极拒绝，无法连接。'))

During handling of the above exception, another exception occurred:

Traceback (most recent call last):
  File "D:\code\apiauto\接口\test_login.py", line 41, in test_login_success
    res = visit(self.data['url'], self.data['data'], self.data['headers'])
  File "D:\code\apiauto\接口\d4_unittest.py", line 16, in visit
    res = requests.post(url, json=data, headers=headers)
  File "D:\python\lib\site-packages\requests\api.py", line 117, in post
    return request('post', url, data=data, json=json, **kwargs)
  File "D:\python\lib\site-packages\requests\api.py", line 61, in request
    return session.request(method=method, url=url, **kwargs)
  File "D:\python\lib\site-packages\requests\sessions.py", line 529, in request
    resp = self.send(prep, **send_kwargs)
  File "D:\python\lib\site-packages\requests\sessions.py", line 645, in send
    r = adapter.send(request, **kwargs)
  File "D:\python\lib\site-packages\requests\adapters.py", line 519, in send
    raise ConnectionError(e, request=request)
requests.exceptions.ConnectionError: HTTPConnectionPool(host='localhost', port=5000): Max retries exceeded with url: /login (Caused by NewConnectionError('<urllib3.connection.HTTPConnection object at 0x0000000003564488>: Failed to establish a new connection: [WinError 10061] 由于目标计算机积极拒绝，无法连接。'))

----------------------------------------------------------------------
Ran 2 tests in 2.049s

FAILED (errors=1)
